Workbook

Sheet Readme
A1: Language Coherence Model — Subjects, Concepts and Connectors tables (v0.3)
A2: First pass generated by build_tables.py. The weights are design decisions (blue) and can be edited.
A4: 1. The four axes
A5: Pole | B5: Label | C5: Pronoun | D5: Character | E5: Weight | F5: What goes there
A6: Up | B6: Context | C6: We | D6: Possibility | E6: V | F6: viable, open, possible, alive, future, good
A7: Down | B7: World | C7: That | D7: logical | E7: I | F7: dangerous, sad, closed, inert, past, negation
A8: Right | B8: Imposition | C8: I | D8: Sensory | E8: Lv | F8: raw perception, concrete, body, physical action
A9: Left | B9: Adaptation | C9: You | D9: structural | E9: Gv | F9: relation, judgment, standard, language, the social
A11: 2. Scale and position
A12: Each node has 4 independent weights, integers from 0 to 10 (0 = no weight). Happiness, for example, weighs in V, Lv and Gv and nothing in I.
A13: x = (Lv − Gv) / 2 → x > 0 toward Imposition, x < 0 toward Adaptation. y = (V − I) / 2 → y > 0 toward Context, y < 0 toward World.
A14: Cell (10 × 10): column = ROUNDUP(x + 5), row = ROUNDUP(5 − y), clipped to 1..10. Row 1 = Context, row 10 = World; column 1 = Adaptation, column 10 = Imposition.
A15: ⚠ With even N there is no central cell: x = 0 falls in column 5 and y = 0 in row 5 (Adaptation / Context side). It is a provisional rule.
A16: τ (tension) = MIN(V, I): separates the ambivalent from the neutral, which the centroid collapses to the same point.
A18: 3. How weights are assigned (inheritance down the tree)
A19: type (biological / non_biological / action / quality) → category → subtype: each level ADDS an adjustment. See the Weight_rules sheet.
A20: Valence: SentiWordNet. V += round(6 × positivity), I += round(6 × negativity). They are independent of each other.
A21: Per-axis lists from Unique Host: sensory adjectives → Imposition, judgment or relation → Adaptation (the hand-written list takes precedence over the generated one).
A22: Hand-made concepts: intrinsic danger, intrinsic emotion and state type adjust V/I/Lv/Gv; they take precedence over the first WordNet sense (ghost = illogical).
A23: People and animals: separated by their WordNet lineage (threat, imposes itself, close bond, cares or teaches; domestic, predator).
... A26: 4. What each table contains
A27: Table | B27: Nodes | C27: Contents
A28: Subjects | B28: =COUNTA(Subjects_nodes!A2:A1392) -> 1391 | C28: biological lexicon (people, animals, plants, body, groups) + subject concepts + pronouns
A29: Concepts | B29: =COUNTA(Concepts_nodes!A2:A7677) -> 7676 | C29: non_biological, action and quality lexicon + hand-made concepts (state, illusory, environment, tone, music)
A30: Connectors | B30: =COUNTA(Connectors_nodes!A2:A197) -> 196 | C30: conjunctions, connective adverbs, transition phrases and punctuation
A32: 5. Connectors: time runs vertically
A33: North = future, possibility, condition, purpose and 'we/us' (join, include). South = past, negation, closure, result, exception.
A34: East–West = present: the horizontal band (V = I, y ≈ 0). West = structure (joins, compares, explains); East = the speaker imposes (emphasis, stance).
A35: Each relation in the document has a base weight (Weight_rules sheet). If a word has two roles, they are two nodes: 'so (result)' and 'so that'; 'though (concessive)' and 'though (sentence-initial)'.
A36: The 'Compare' column of Connectors_nodes contrasts the proposed axis with the one of the Unique Host construction.
A38: 6. What is NOT there (limits of this pass)
A39: • The 7 concepts of type 'language' (who, which, where…) were left out of Subjects and Concepts: relatives and interrogatives now live in Connectors.
A40: • 261 concepts that are inflections of another word are not separate nodes.
A41: • 'he, she, they, him, her, this, these' are not in any Unique Host pronoun list and were not placed.
A42: • Links (v0.4): 'Related (nodes)' comes from the 597 hand-made concepts; 'Related (WordNet)' is derived from WordNet (is-a, kind-of, part, derived, similar, definition); 'Related (manual)' is a hand-written narrative seed (tools/related_manual.py); 'Opposites' are WordNet antonyms. State labels (hostile, defenseless…) are listed separately because they are not nodes.
A43: • People are still concentrated: the tree has almost no words in its person leaves (237 in total, no sub-leaves).
A44: • SentiWordNet valence is noisy for nouns; the extremes (rows 1 and 10) should be reviewed by hand.
A45: • Only base forms of verbs exist: tense (past = World, future = Context) does not yet move the weight of an action.

Sheet Subjects
A1: Table of Subjects (10 × 10)
A2: Each cell shows how many words it has and the first ones (hand-made concepts first). Full list in the sheet Subjects_nodes. Position: x = (Lv − Gv)/2, y = (V − I)/2.
C4: ◄ Adaptation (You, structural) | H4: Imposition (I, Sensory) ►
C5: 1 | D5: 2 | E5: 3 | F5: 4 | G5: 5 | H5: 6 | I5: 7 | J5: 8 | K5: 9 | L5: 10
A6: Context (We, Possibility) ▲ | B6: 1 | C6: 91 children, members, child, kids, son, baby … +85 | D6: 2 father, mother | E6: 10 santa, researchers, masters, fool, researcher, fools … +4 | G6: 5 we, us, our, ours, ourselves | H6: 2 duke, archbishop
B7: 2 | C7: 116 author, doctor, professor, teacher, artist, teachers … +110 | E7: 498 man, god, women, men, friends, guys … +492 | F7: 4 person, angelo, saint, saints | G7: 3 flowers, flower, bud | H7: 153 president, players, player, king, director, minister … +147 | I7: 1 hero
B8: 3 | C8: 4 you, your, yours, yourself | D8: 3 dog, dogs, puppy | E8: 183 he, she, they, him, her, his … +177 | F8: 20 fish, bird, pet, character, michael, characters … +14 | G8: 51 tree, trees, fruit, bush, root, alexander … +45 | H8: 7 cops, cop, administrator, loser, administrators, losers … +1 | K8: 4 hand, eye, ear, ears | L8: 5 i, me, my, mine, myself
B9: 4 | D9: 9 victim, victims, prisoners, prisoner, survivors, survivor … +3 | E9: 21 bull, mouse, pig, mice, insects, pigs … +15 | F9: 4 animals, animal, hydra, phantom | G9: 2 cole, sneak | I9: 2 brain, brains | J9: 13 body, bodies, gene, flesh, genes, sweat … +7 | K9: 59 head, hair, ass, feet, skin, foot … +53 | L9: 1 face
B10: 5 | D10: 3 patients, patient, casualties | E10: 5 hunt, mercenary, zombie, stalker, cultist | F10: 11 cat, fox, cats, lion, eagles, lions … +5 | G10: 11 blades, punk, runner, highwayman, swindler, cutthroat … +5 | H10: 2 bandit, warlord | I10: 19 bone, muscle, stomach, tissue, vessel, vessels … +13
B11: 6 | D11: 2 vagrant, invalid | E11: 10 killer, spider, burns, widow, killers, enemies … +4 | F11: 8 monster, monsters, goblin, troll, vampire, werewolf … +2 | G11: 11 stranger, ted, hood, criminals, strangers, rogue … +5 | H11: 2 villain, tyrant
B12: 7 | E12: 7 dragon, snake, sharks, snakes, shark, beast … +1 | F12: 1 dragons | G12: 1 liar | J12: 1 blood | K12: 2 fang, claw
B13: 8 | F13: 2 wolf, wolves | G13: 12 thief, assassin, raider, pirate, pirates, raiders … +6
B14: 9 | G14: 2 outlaw, ogre | J14: 2 this, these
A15: World (That, logical) ▼ | B15: 10 | G15: 4 that, it, those, itself
A18: Count per cell (COUNTIFS formulas over Subjects_nodes)
C19: 1 | D19: 2 | E19: 3 | F19: 4 | G19: 5 | H19: 6 | I19: 7 | J19: 8 | K19: 9 | L19: 10
B20: 1 | C20: =COUNTIFS(Subjects_nodes!$K$2:$K$1392,C$19,Subjects_nodes!$L$2:$L$1392,$B20) -> 91 | D20: =COUNTIFS(Subjects_nodes!$K$2:$K$1392,D$19,Subjects_nodes!$L$2:$L$1392,$B20) -> 2 | E20: =COUNTIFS(Subjects_nodes!$K$2:$K$1392,E$19,Subjects_nodes!$L$2:$L$1392,$B20) -> 10 | F20: =COUNTIFS(Subjects_nodes!$K$2:$K$1392,F$19,Subjects_nodes!$L$2:$L$1392,$B20) -> 0 | G20: =COUNTIFS(Subjects_nodes!$K$2:$K$1392,G$19,Subjects_nodes!$L$2:$L$1392,$B20) -> 5 | H20: =COUNTIFS(Subjects_nodes!$K$2:$K$1392,H$19,Subjects_nodes!$L$2:$L$1392,$B20) -> 2 | I20: =COUNTIFS(Subjects_nodes!$K$2:$K$1392,I$19,Subjects_nodes!$L$2:$L$1392,$B20) -> 0 | J20: =COUNTIFS(Subjects_nodes!$K$2:$K$1392,J$19,Subjects_nodes!$L$2:$L$1392,$B20) -> 0 | ... L20: =COUNTIFS(Subjects_nodes!$K$2:$K$1392,L$19,Subjects_nodes!$L$2:$L$1392,$B20) -> 0
B21: 2 | C21: =COUNTIFS(Subjects_nodes!$K$2:$K$1392,C$19,Subjects_nodes!$L$2:$L$1392,$B21) -> 116 | D21: =COUNTIFS(Subjects_nodes!$K$2:$K$1392,D$19,Subjects_nodes!$L$2:$L$1392,$B21) -> 0 | E21: =COUNTIFS(Subjects_nodes!$K$2:$K$1392,E$19,Subjects_nodes!$L$2:$L$1392,$B21) -> 498 | F21: =COUNTIFS(Subjects_nodes!$K$2:$K$1392,F$19,Subjects_nodes!$L$2:$L$1392,$B21) -> 4 | G21: =COUNTIFS(Subjects_nodes!$K$2:$K$1392,G$19,Subjects_nodes!$L$2:$L$1392,$B21) -> 3 | H21: =COUNTIFS(Subjects_nodes!$K$2:$K$1392,H$19,Subjects_nodes!$L$2:$L$1392,$B21) -> 153 | I21: =COUNTIFS(Subjects_nodes!$K$2:$K$1392,I$19,Subjects_nodes!$L$2:$L$1392,$B21) -> 1 | J21: =COUNTIFS(Subjects_nodes!$K$2:$K$1392,J$19,Subjects_nodes!$L$2:$L$1392,$B21) -> 0 | ... L21: =COUNTIFS(Subjects_nodes!$K$2:$K$1392,L$19,Subjects_nodes!$L$2:$L$1392,$B21) -> 0
B22: 3 | C22: =COUNTIFS(Subjects_nodes!$K$2:$K$1392,C$19,Subjects_nodes!$L$2:$L$1392,$B22) -> 4 | D22: =COUNTIFS(Subjects_nodes!$K$2:$K$1392,D$19,Subjects_nodes!$L$2:$L$1392,$B22) -> 3 | E22: =COUNTIFS(Subjects_nodes!$K$2:$K$1392,E$19,Subjects_nodes!$L$2:$L$1392,$B22) -> 183 | F22: =COUNTIFS(Subjects_nodes!$K$2:$K$1392,F$19,Subjects_nodes!$L$2:$L$1392,$B22) -> 20 | G22: =COUNTIFS(Subjects_nodes!$K$2:$K$1392,G$19,Subjects_nodes!$L$2:$L$1392,$B22) -> 51 | H22: =COUNTIFS(Subjects_nodes!$K$2:$K$1392,H$19,Subjects_nodes!$L$2:$L$1392,$B22) -> 7 | I22: =COUNTIFS(Subjects_nodes!$K$2:$K$1392,I$19,Subjects_nodes!$L$2:$L$1392,$B22) -> 0 | J22: =COUNTIFS(Subjects_nodes!$K$2:$K$1392,J$19,Subjects_nodes!$L$2:$L$1392,$B22) -> 0 | ... L22: =COUNTIFS(Subjects_nodes!$K$2:$K$1392,L$19,Subjects_nodes!$L$2:$L$1392,$B22) -> 5
B23: 4 | C23: =COUNTIFS(Subjects_nodes!$K$2:$K$1392,C$19,Subjects_nodes!$L$2:$L$1392,$B23) -> 0 | D23: =COUNTIFS(Subjects_nodes!$K$2:$K$1392,D$19,Subjects_nodes!$L$2:$L$1392,$B23) -> 9 | E23: =COUNTIFS(Subjects_nodes!$K$2:$K$1392,E$19,Subjects_nodes!$L$2:$L$1392,$B23) -> 21 | F23: =COUNTIFS(Subjects_nodes!$K$2:$K$1392,F$19,Subjects_nodes!$L$2:$L$1392,$B23) -> 4 | G23: =COUNTIFS(Subjects_nodes!$K$2:$K$1392,G$19,Subjects_nodes!$L$2:$L$1392,$B23) -> 2 | H23: =COUNTIFS(Subjects_nodes!$K$2:$K$1392,H$19,Subjects_nodes!$L$2:$L$1392,$B23) -> 0 | I23: =COUNTIFS(Subjects_nodes!$K$2:$K$1392,I$19,Subjects_nodes!$L$2:$L$1392,$B23) -> 2 | J23: =COUNTIFS(Subjects_nodes!$K$2:$K$1392,J$19,Subjects_nodes!$L$2:$L$1392,$B23) -> 13 | ... L23: =COUNTIFS(Subjects_nodes!$K$2:$K$1392,L$19,Subjects_nodes!$L$2:$L$1392,$B23) -> 1
B24: 5 | C24: =COUNTIFS(Subjects_nodes!$K$2:$K$1392,C$19,Subjects_nodes!$L$2:$L$1392,$B24) -> 0 | D24: =COUNTIFS(Subjects_nodes!$K$2:$K$1392,D$19,Subjects_nodes!$L$2:$L$1392,$B24) -> 3 | E24: =COUNTIFS(Subjects_nodes!$K$2:$K$1392,E$19,Subjects_nodes!$L$2:$L$1392,$B24) -> 5 | F24: =COUNTIFS(Subjects_nodes!$K$2:$K$1392,F$19,Subjects_nodes!$L$2:$L$1392,$B24) -> 11 | G24: =COUNTIFS(Subjects_nodes!$K$2:$K$1392,G$19,Subjects_nodes!$L$2:$L$1392,$B24) -> 11 | H24: =COUNTIFS(Subjects_nodes!$K$2:$K$1392,H$19,Subjects_nodes!$L$2:$L$1392,$B24) -> 2 | I24: =COUNTIFS(Subjects_nodes!$K$2:$K$1392,I$19,Subjects_nodes!$L$2:$L$1392,$B24) -> 19 | J24: =COUNTIFS(Subjects_nodes!$K$2:$K$1392,J$19,Subjects_nodes!$L$2:$L$1392,$B24) -> 0 | ... L24: =COUNTIFS(Subjects_nodes!$K$2:$K$1392,L$19,Subjects_nodes!$L$2:$L$1392,$B24) -> 0
B25: 6 | C25: =COUNTIFS(Subjects_nodes!$K$2:$K$1392,C$19,Subjects_nodes!$L$2:$L$1392,$B25) -> 0 | D25: =COUNTIFS(Subjects_nodes!$K$2:$K$1392,D$19,Subjects_nodes!$L$2:$L$1392,$B25) -> 2 | E25: =COUNTIFS(Subjects_nodes!$K$2:$K$1392,E$19,Subjects_nodes!$L$2:$L$1392,$B25) -> 10 | F25: =COUNTIFS(Subjects_nodes!$K$2:$K$1392,F$19,Subjects_nodes!$L$2:$L$1392,$B25) -> 8 | G25: =COUNTIFS(Subjects_nodes!$K$2:$K$1392,G$19,Subjects_nodes!$L$2:$L$1392,$B25) -> 11 | H25: =COUNTIFS(Subjects_nodes!$K$2:$K$1392,H$19,Subjects_nodes!$L$2:$L$1392,$B25) -> 2 | I25: =COUNTIFS(Subjects_nodes!$K$2:$K$1392,I$19,Subjects_nodes!$L$2:$L$1392,$B25) -> 0 | J25: =COUNTIFS(Subjects_nodes!$K$2:$K$1392,J$19,Subjects_nodes!$L$2:$L$1392,$B25) -> 0 | ... L25: =COUNTIFS(Subjects_nodes!$K$2:$K$1392,L$19,Subjects_nodes!$L$2:$L$1392,$B25) -> 0
B26: 7 | C26: =COUNTIFS(Subjects_nodes!$K$2:$K$1392,C$19,Subjects_nodes!$L$2:$L$1392,$B26) -> 0 | D26: =COUNTIFS(Subjects_nodes!$K$2:$K$1392,D$19,Subjects_nodes!$L$2:$L$1392,$B26) -> 0 | E26: =COUNTIFS(Subjects_nodes!$K$2:$K$1392,E$19,Subjects_nodes!$L$2:$L$1392,$B26) -> 7 | F26: =COUNTIFS(Subjects_nodes!$K$2:$K$1392,F$19,Subjects_nodes!$L$2:$L$1392,$B26) -> 1 | G26: =COUNTIFS(Subjects_nodes!$K$2:$K$1392,G$19,Subjects_nodes!$L$2:$L$1392,$B26) -> 1 | H26: =COUNTIFS(Subjects_nodes!$K$2:$K$1392,H$19,Subjects_nodes!$L$2:$L$1392,$B26) -> 0 | I26: =COUNTIFS(Subjects_nodes!$K$2:$K$1392,I$19,Subjects_nodes!$L$2:$L$1392,$B26) -> 0 | J26: =COUNTIFS(Subjects_nodes!$K$2:$K$1392,J$19,Subjects_nodes!$L$2:$L$1392,$B26) -> 1 | ... L26: =COUNTIFS(Subjects_nodes!$K$2:$K$1392,L$19,Subjects_nodes!$L$2:$L$1392,$B26) -> 0
B27: 8 | C27: =COUNTIFS(Subjects_nodes!$K$2:$K$1392,C$19,Subjects_nodes!$L$2:$L$1392,$B27) -> 0 | D27: =COUNTIFS(Subjects_nodes!$K$2:$K$1392,D$19,Subjects_nodes!$L$2:$L$1392,$B27) -> 0 | E27: =COUNTIFS(Subjects_nodes!$K$2:$K$1392,E$19,Subjects_nodes!$L$2:$L$1392,$B27) -> 0 | F27: =COUNTIFS(Subjects_nodes!$K$2:$K$1392,F$19,Subjects_nodes!$L$2:$L$1392,$B27) -> 2 | G27: =COUNTIFS(Subjects_nodes!$K$2:$K$1392,G$19,Subjects_nodes!$L$2:$L$1392,$B27) -> 12 | H27: =COUNTIFS(Subjects_nodes!$K$2:$K$1392,H$19,Subjects_nodes!$L$2:$L$1392,$B27) -> 0 | I27: =COUNTIFS(Subjects_nodes!$K$2:$K$1392,I$19,Subjects_nodes!$L$2:$L$1392,$B27) -> 0 | J27: =COUNTIFS(Subjects_nodes!$K$2:$K$1392,J$19,Subjects_nodes!$L$2:$L$1392,$B27) -> 0 | ... L27: =COUNTIFS(Subjects_nodes!$K$2:$K$1392,L$19,Subjects_nodes!$L$2:$L$1392,$B27) -> 0
B28: 9 | C28: =COUNTIFS(Subjects_nodes!$K$2:$K$1392,C$19,Subjects_nodes!$L$2:$L$1392,$B28) -> 0 | D28: =COUNTIFS(Subjects_nodes!$K$2:$K$1392,D$19,Subjects_nodes!$L$2:$L$1392,$B28) -> 0 | E28: =COUNTIFS(Subjects_nodes!$K$2:$K$1392,E$19,Subjects_nodes!$L$2:$L$1392,$B28) -> 0 | F28: =COUNTIFS(Subjects_nodes!$K$2:$K$1392,F$19,Subjects_nodes!$L$2:$L$1392,$B28) -> 0 | G28: =COUNTIFS(Subjects_nodes!$K$2:$K$1392,G$19,Subjects_nodes!$L$2:$L$1392,$B28) -> 2 | H28: =COUNTIFS(Subjects_nodes!$K$2:$K$1392,H$19,Subjects_nodes!$L$2:$L$1392,$B28) -> 0 | I28: =COUNTIFS(Subjects_nodes!$K$2:$K$1392,I$19,Subjects_nodes!$L$2:$L$1392,$B28) -> 0 | J28: =COUNTIFS(Subjects_nodes!$K$2:$K$1392,J$19,Subjects_nodes!$L$2:$L$1392,$B28) -> 2 | ... L28: =COUNTIFS(Subjects_nodes!$K$2:$K$1392,L$19,Subjects_nodes!$L$2:$L$1392,$B28) -> 0
B29: 10 | C29: =COUNTIFS(Subjects_nodes!$K$2:$K$1392,C$19,Subjects_nodes!$L$2:$L$1392,$B29) -> 0 | D29: =COUNTIFS(Subjects_nodes!$K$2:$K$1392,D$19,Subjects_nodes!$L$2:$L$1392,$B29) -> 0 | E29: =COUNTIFS(Subjects_nodes!$K$2:$K$1392,E$19,Subjects_nodes!$L$2:$L$1392,$B29) -> 0 | F29: =COUNTIFS(Subjects_nodes!$K$2:$K$1392,F$19,Subjects_nodes!$L$2:$L$1392,$B29) -> 0 | G29: =COUNTIFS(Subjects_nodes!$K$2:$K$1392,G$19,Subjects_nodes!$L$2:$L$1392,$B29) -> 4 | H29: =COUNTIFS(Subjects_nodes!$K$2:$K$1392,H$19,Subjects_nodes!$L$2:$L$1392,$B29) -> 0 | I29: =COUNTIFS(Subjects_nodes!$K$2:$K$1392,I$19,Subjects_nodes!$L$2:$L$1392,$B29) -> 0 | J29: =COUNTIFS(Subjects_nodes!$K$2:$K$1392,J$19,Subjects_nodes!$L$2:$L$1392,$B29) -> 0 | ... L29: =COUNTIFS(Subjects_nodes!$K$2:$K$1392,L$19,Subjects_nodes!$L$2:$L$1392,$B29) -> 0
B30: Total | C30: =SUM(C20:L29) -> 1391 | D30: nodes in the sheet: | E30: =COUNTA(Subjects_nodes!A2:A1392) -> 1391 | F30: =IF(C30=E30,"✔ matches","✖ does not match") -> ✔ matches

Sheet Concepts
A1: Table of Concepts (10 × 10)
A2: Each cell shows how many words it has and the first ones (hand-made concepts first). Full list in the sheet Concepts_nodes. Position: x = (Lv − Gv)/2, y = (V − I)/2.
C4: ◄ Adaptation (You, structural) | H4: Imposition (I, Sensory) ►
C5: 1 | D5: 2 | E5: 3 | F5: 4 | G5: 5 | H5: 6 | I5: 7 | J5: 8 | K5: 9 | L5: 10
A6: Context (We, Possibility) ▲ | B6: 1 | C6: 1 excellent | E6: 1 dream | J6: 3 passion, favour, desired | K6: 2 hope, ambition
B7: 2 | C7: 25 best, better, nice, beautiful, perfect, successful … +19 | D7: 16 important, happy, smart, healthy, correct, intellectual … +10 | E7: 10 plan, goal, joke, vision, intention, jokes … +4 | G7: 2 sexy, enthusiastic | H7: 6 captured, capture, renewed, decorated, fulfill, copied | I7: 8 enjoy, loved, loves, enjoyed, loving, enjoying … +2 | J7: 14 desire, pleasure, joy, emotions, emotion, preference … +8 | K7: 1 pride
B8: 3 | C8: 63 different, fine, amazing, interesting, welcome, grand … +57 | D8: 80 clear, worth, financial, fair, significant, rich … +74 | E8: 166 music, eyes, truth, respect, method, taste … +160 | F8: 70 goods, popularity, asset, goodness, reliability, try … +64 | G8: 8 aware, proud, alive, emotional, alert, eager … +2 | H8: 81 opportunity, written, built, published, writing, created … +75 | I8: 16 project, courtesy, interested, liked, likes, prefer … +10 | J8: 119 love, relief, excitement, satisfaction, gratitude, attachment … +113 | K8: 8 hopes, ego, wonders, awe, hoping, hoped … +2
B9: 4 | C9: 103 same, public, available, similar, private, super … +97 | D9: 343 new, high, sure, national, american, social … +337 | E9: 1290 point, order, news, book, information, thanks … +1284 | F9: 276 kind, self, urgent, quality, ability, beauty … +270 | G9: 23 name, trust, profit, assets, treasure, trusts … +17 | H9: 40 westminster, incentive, incentives, bliss, added, add … +34 | I9: 127 melody, safe, training, favor, reform, approval … +121 | J9: 292 feelings, mood, jam, soup, roast, vodka … +286 | K9: 79 turtle, used, using, fuck, eat, released … +73 | L9: 88 run, walk, fly, hide, breathe, duck … +82
B10: 5 | C10: 34 poor, funny, worst, magic, severe, relative … +28 | D10: 71 real, less, late, likely, sorry, average … +65 | E10: 200 part, future, heart, rest, relationship, percent … +194 | F10: 431 good, way, power, level, control, age … +425 | G10: 111 be, things, cost, land, share, gold … +105 | H10: 315 money, identity, office, john, reason, building … +309 | I10: 469 house, room, door, window, angry, work … +463 | J10: 52 pity, compassion, screams, screaming, scream, auditory_silence … +46 | K10: 218 dress, clothes, suit, shirt, cap, tie … +212 | L10: 8 missing, missed, suffering, suffered, suffer, smells … +2
B11: 6 | C11: 20 striking, worse, offensive, horrible, annoying, silly … +14 | D11: 25 sad, cheap, false, dirty, secondary, steady … +19 | E11: 23 scale, bias, curse, apology, scales, autism … +17 | F11: 119 number, lot, nothing, bit, size, increase … +113 | G11: 17 amount, effects, option, options, amounts, premium … +11 | H11: 361 home, state, city, top, states, side … +355 | I11: 127 terrified, care, bank, sea, success, river … +121 | J11: 333 place, night, light, street, forest, alarm … +327 | K11: 116 rage, envy, outrage, car, cup, bed … +110
B12: 7 | C12: 5 terrible, awful, notorious, negative, unfortunate | D12: 7 fake, painful, nasty, abusive, filthy, miserable … +1 | E12: 144 wraith, arrows, year, years, day, days … +138 | F12: 9 executed, trapped, execute, mysterious, limit, scores … +3 | G12: 26 tone, alone, group, space, event, feeling … +20 | H12: 354 burn, burning, burned, burnt, life, thing … +348 | I12: 170 food, tortured, slash, choke, strangle, lunge … +164 | J12: 163 surprise, disappointment, surprises, surprised, scared, feared … +157 | K12: 151 hatred, frustration, fury, temper, tired, smoking … +145 | L12: 2 water, keys
B13: 8 | D13: 1 lonely | E13: 3 hours, fall, era | F13: 6 abandoned, threatened, murdered, threatening, threaten, poisoning | G13: 3 afraid, quantity, quantities | H13: 37 prison, cage, dungeon, prisons, died, die … +31 | I13: 26 shot, punch, slaughter, shooting, shoot, fired … +20 | J13: 20 fear, shame, shock, horror, panic, terror … +14 | K13: 34 anger, killed, kill, struck, kills, flooding … +28 | L13: 3 hurt, hurts, hurting
B14: 9 | D14: 1 dead | E14: 1 history | F14: 2 lost, bad | H14: 9 poverty, ruin, unemployment, disability, guilt, disabilities … +3 | I14: 14 attack, murder, attacks, strike, assault, strikes … +8 | J14: 10 chain, knife, torture, knives, axe, surprising … +4 | K14: 2 spite, wounded
A15: World (That, logical) ▼ | B15: 10 | F15: 4 mourn, betrayal, hopeless, orphan | G15: 1 dehumanization | H15: 14 pain, injury, injuries, wound, collapse, flame … +8 | I15: 27 death, fire, killing, smoke, storm, threat … +21 | J15: 1 poison | K15: 15 blade, gun, guns, bomb, sword, rifle … +9
A18: Count per cell (COUNTIFS formulas over Concepts_nodes)
C19: 1 | D19: 2 | E19: 3 | F19: 4 | G19: 5 | H19: 6 | I19: 7 | J19: 8 | K19: 9 | L19: 10
B20: 1 | C20: =COUNTIFS(Concepts_nodes!$K$2:$K$7677,C$19,Concepts_nodes!$L$2:$L$7677,$B20) -> 1 | D20: =COUNTIFS(Concepts_nodes!$K$2:$K$7677,D$19,Concepts_nodes!$L$2:$L$7677,$B20) -> 0 | E20: =COUNTIFS(Concepts_nodes!$K$2:$K$7677,E$19,Concepts_nodes!$L$2:$L$7677,$B20) -> 1 | F20: =COUNTIFS(Concepts_nodes!$K$2:$K$7677,F$19,Concepts_nodes!$L$2:$L$7677,$B20) -> 0 | G20: =COUNTIFS(Concepts_nodes!$K$2:$K$7677,G$19,Concepts_nodes!$L$2:$L$7677,$B20) -> 0 | H20: =COUNTIFS(Concepts_nodes!$K$2:$K$7677,H$19,Concepts_nodes!$L$2:$L$7677,$B20) -> 0 | I20: =COUNTIFS(Concepts_nodes!$K$2:$K$7677,I$19,Concepts_nodes!$L$2:$L$7677,$B20) -> 0 | J20: =COUNTIFS(Concepts_nodes!$K$2:$K$7677,J$19,Concepts_nodes!$L$2:$L$7677,$B20) -> 3 | ... L20: =COUNTIFS(Concepts_nodes!$K$2:$K$7677,L$19,Concepts_nodes!$L$2:$L$7677,$B20) -> 0
B21: 2 | C21: =COUNTIFS(Concepts_nodes!$K$2:$K$7677,C$19,Concepts_nodes!$L$2:$L$7677,$B21) -> 25 | D21: =COUNTIFS(Concepts_nodes!$K$2:$K$7677,D$19,Concepts_nodes!$L$2:$L$7677,$B21) -> 16 | E21: =COUNTIFS(Concepts_nodes!$K$2:$K$7677,E$19,Concepts_nodes!$L$2:$L$7677,$B21) -> 10 | F21: =COUNTIFS(Concepts_nodes!$K$2:$K$7677,F$19,Concepts_nodes!$L$2:$L$7677,$B21) -> 0 | G21: =COUNTIFS(Concepts_nodes!$K$2:$K$7677,G$19,Concepts_nodes!$L$2:$L$7677,$B21) -> 2 | H21: =COUNTIFS(Concepts_nodes!$K$2:$K$7677,H$19,Concepts_nodes!$L$2:$L$7677,$B21) -> 6 | I21: =COUNTIFS(Concepts_nodes!$K$2:$K$7677,I$19,Concepts_nodes!$L$2:$L$7677,$B21) -> 8 | J21: =COUNTIFS(Concepts_nodes!$K$2:$K$7677,J$19,Concepts_nodes!$L$2:$L$7677,$B21) -> 14 | ... L21: =COUNTIFS(Concepts_nodes!$K$2:$K$7677,L$19,Concepts_nodes!$L$2:$L$7677,$B21) -> 0
B22: 3 | C22: =COUNTIFS(Concepts_nodes!$K$2:$K$7677,C$19,Concepts_nodes!$L$2:$L$7677,$B22) -> 63 | D22: =COUNTIFS(Concepts_nodes!$K$2:$K$7677,D$19,Concepts_nodes!$L$2:$L$7677,$B22) -> 80 | E22: =COUNTIFS(Concepts_nodes!$K$2:$K$7677,E$19,Concepts_nodes!$L$2:$L$7677,$B22) -> 166 | F22: =COUNTIFS(Concepts_nodes!$K$2:$K$7677,F$19,Concepts_nodes!$L$2:$L$7677,$B22) -> 70 | G22: =COUNTIFS(Concepts_nodes!$K$2:$K$7677,G$19,Concepts_nodes!$L$2:$L$7677,$B22) -> 8 | H22: =COUNTIFS(Concepts_nodes!$K$2:$K$7677,H$19,Concepts_nodes!$L$2:$L$7677,$B22) -> 81 | I22: =COUNTIFS(Concepts_nodes!$K$2:$K$7677,I$19,Concepts_nodes!$L$2:$L$7677,$B22) -> 16 | J22: =COUNTIFS(Concepts_nodes!$K$2:$K$7677,J$19,Concepts_nodes!$L$2:$L$7677,$B22) -> 119 | ... L22: =COUNTIFS(Concepts_nodes!$K$2:$K$7677,L$19,Concepts_nodes!$L$2:$L$7677,$B22) -> 0
B23: 4 | C23: =COUNTIFS(Concepts_nodes!$K$2:$K$7677,C$19,Concepts_nodes!$L$2:$L$7677,$B23) -> 103 | D23: =COUNTIFS(Concepts_nodes!$K$2:$K$7677,D$19,Concepts_nodes!$L$2:$L$7677,$B23) -> 343 | E23: =COUNTIFS(Concepts_nodes!$K$2:$K$7677,E$19,Concepts_nodes!$L$2:$L$7677,$B23) -> 1290 | F23: =COUNTIFS(Concepts_nodes!$K$2:$K$7677,F$19,Concepts_nodes!$L$2:$L$7677,$B23) -> 276 | G23: =COUNTIFS(Concepts_nodes!$K$2:$K$7677,G$19,Concepts_nodes!$L$2:$L$7677,$B23) -> 23 | H23: =COUNTIFS(Concepts_nodes!$K$2:$K$7677,H$19,Concepts_nodes!$L$2:$L$7677,$B23) -> 40 | I23: =COUNTIFS(Concepts_nodes!$K$2:$K$7677,I$19,Concepts_nodes!$L$2:$L$7677,$B23) -> 127 | J23: =COUNTIFS(Concepts_nodes!$K$2:$K$7677,J$19,Concepts_nodes!$L$2:$L$7677,$B23) -> 292 | ... L23: =COUNTIFS(Concepts_nodes!$K$2:$K$7677,L$19,Concepts_nodes!$L$2:$L$7677,$B23) -> 88
B24: 5 | C24: =COUNTIFS(Concepts_nodes!$K$2:$K$7677,C$19,Concepts_nodes!$L$2:$L$7677,$B24) -> 34 | D24: =COUNTIFS(Concepts_nodes!$K$2:$K$7677,D$19,Concepts_nodes!$L$2:$L$7677,$B24) -> 71 | E24: =COUNTIFS(Concepts_nodes!$K$2:$K$7677,E$19,Concepts_nodes!$L$2:$L$7677,$B24) -> 200 | F24: =COUNTIFS(Concepts_nodes!$K$2:$K$7677,F$19,Concepts_nodes!$L$2:$L$7677,$B24) -> 431 | G24: =COUNTIFS(Concepts_nodes!$K$2:$K$7677,G$19,Concepts_nodes!$L$2:$L$7677,$B24) -> 111 | H24: =COUNTIFS(Concepts_nodes!$K$2:$K$7677,H$19,Concepts_nodes!$L$2:$L$7677,$B24) -> 315 | I24: =COUNTIFS(Concepts_nodes!$K$2:$K$7677,I$19,Concepts_nodes!$L$2:$L$7677,$B24) -> 469 | J24: =COUNTIFS(Concepts_nodes!$K$2:$K$7677,J$19,Concepts_nodes!$L$2:$L$7677,$B24) -> 52 | ... L24: =COUNTIFS(Concepts_nodes!$K$2:$K$7677,L$19,Concepts_nodes!$L$2:$L$7677,$B24) -> 8
B25: 6 | C25: =COUNTIFS(Concepts_nodes!$K$2:$K$7677,C$19,Concepts_nodes!$L$2:$L$7677,$B25) -> 20 | D25: =COUNTIFS(Concepts_nodes!$K$2:$K$7677,D$19,Concepts_nodes!$L$2:$L$7677,$B25) -> 25 | E25: =COUNTIFS(Concepts_nodes!$K$2:$K$7677,E$19,Concepts_nodes!$L$2:$L$7677,$B25) -> 23 | F25: =COUNTIFS(Concepts_nodes!$K$2:$K$7677,F$19,Concepts_nodes!$L$2:$L$7677,$B25) -> 119 | G25: =COUNTIFS(Concepts_nodes!$K$2:$K$7677,G$19,Concepts_nodes!$L$2:$L$7677,$B25) -> 17 | H25: =COUNTIFS(Concepts_nodes!$K$2:$K$7677,H$19,Concepts_nodes!$L$2:$L$7677,$B25) -> 361 | I25: =COUNTIFS(Concepts_nodes!$K$2:$K$7677,I$19,Concepts_nodes!$L$2:$L$7677,$B25) -> 127 | J25: =COUNTIFS(Concepts_nodes!$K$2:$K$7677,J$19,Concepts_nodes!$L$2:$L$7677,$B25) -> 333 | ... L25: =COUNTIFS(Concepts_nodes!$K$2:$K$7677,L$19,Concepts_nodes!$L$2:$L$7677,$B25) -> 0
B26: 7 | C26: =COUNTIFS(Concepts_nodes!$K$2:$K$7677,C$19,Concepts_nodes!$L$2:$L$7677,$B26) -> 5 | D26: =COUNTIFS(Concepts_nodes!$K$2:$K$7677,D$19,Concepts_nodes!$L$2:$L$7677,$B26) -> 7 | E26: =COUNTIFS(Concepts_nodes!$K$2:$K$7677,E$19,Concepts_nodes!$L$2:$L$7677,$B26) -> 144 | F26: =COUNTIFS(Concepts_nodes!$K$2:$K$7677,F$19,Concepts_nodes!$L$2:$L$7677,$B26) -> 9 | G26: =COUNTIFS(Concepts_nodes!$K$2:$K$7677,G$19,Concepts_nodes!$L$2:$L$7677,$B26) -> 26 | H26: =COUNTIFS(Concepts_nodes!$K$2:$K$7677,H$19,Concepts_nodes!$L$2:$L$7677,$B26) -> 354 | I26: =COUNTIFS(Concepts_nodes!$K$2:$K$7677,I$19,Concepts_nodes!$L$2:$L$7677,$B26) -> 170 | J26: =COUNTIFS(Concepts_nodes!$K$2:$K$7677,J$19,Concepts_nodes!$L$2:$L$7677,$B26) -> 163 | ... L26: =COUNTIFS(Concepts_nodes!$K$2:$K$7677,L$19,Concepts_nodes!$L$2:$L$7677,$B26) -> 2
B27: 8 | C27: =COUNTIFS(Concepts_nodes!$K$2:$K$7677,C$19,Concepts_nodes!$L$2:$L$7677,$B27) -> 0 | D27: =COUNTIFS(Concepts_nodes!$K$2:$K$7677,D$19,Concepts_nodes!$L$2:$L$7677,$B27) -> 1 | E27: =COUNTIFS(Concepts_nodes!$K$2:$K$7677,E$19,Concepts_nodes!$L$2:$L$7677,$B27) -> 3 | F27: =COUNTIFS(Concepts_nodes!$K$2:$K$7677,F$19,Concepts_nodes!$L$2:$L$7677,$B27) -> 6 | G27: =COUNTIFS(Concepts_nodes!$K$2:$K$7677,G$19,Concepts_nodes!$L$2:$L$7677,$B27) -> 3 | H27: =COUNTIFS(Concepts_nodes!$K$2:$K$7677,H$19,Concepts_nodes!$L$2:$L$7677,$B27) -> 37 | I27: =COUNTIFS(Concepts_nodes!$K$2:$K$7677,I$19,Concepts_nodes!$L$2:$L$7677,$B27) -> 26 | J27: =COUNTIFS(Concepts_nodes!$K$2:$K$7677,J$19,Concepts_nodes!$L$2:$L$7677,$B27) -> 20 | ... L27: =COUNTIFS(Concepts_nodes!$K$2:$K$7677,L$19,Concepts_nodes!$L$2:$L$7677,$B27) -> 3
B28: 9 | C28: =COUNTIFS(Concepts_nodes!$K$2:$K$7677,C$19,Concepts_nodes!$L$2:$L$7677,$B28) -> 0 | D28: =COUNTIFS(Concepts_nodes!$K$2:$K$7677,D$19,Concepts_nodes!$L$2:$L$7677,$B28) -> 1 | E28: =COUNTIFS(Concepts_nodes!$K$2:$K$7677,E$19,Concepts_nodes!$L$2:$L$7677,$B28) -> 1 | F28: =COUNTIFS(Concepts_nodes!$K$2:$K$7677,F$19,Concepts_nodes!$L$2:$L$7677,$B28) -> 2 | G28: =COUNTIFS(Concepts_nodes!$K$2:$K$7677,G$19,Concepts_nodes!$L$2:$L$7677,$B28) -> 0 | H28: =COUNTIFS(Concepts_nodes!$K$2:$K$7677,H$19,Concepts_nodes!$L$2:$L$7677,$B28) -> 9 | I28: =COUNTIFS(Concepts_nodes!$K$2:$K$7677,I$19,Concepts_nodes!$L$2:$L$7677,$B28) -> 14 | J28: =COUNTIFS(Concepts_nodes!$K$2:$K$7677,J$19,Concepts_nodes!$L$2:$L$7677,$B28) -> 10 | ... L28: =COUNTIFS(Concepts_nodes!$K$2:$K$7677,L$19,Concepts_nodes!$L$2:$L$7677,$B28) -> 0
B29: 10 | C29: =COUNTIFS(Concepts_nodes!$K$2:$K$7677,C$19,Concepts_nodes!$L$2:$L$7677,$B29) -> 0 | D29: =COUNTIFS(Concepts_nodes!$K$2:$K$7677,D$19,Concepts_nodes!$L$2:$L$7677,$B29) -> 0 | E29: =COUNTIFS(Concepts_nodes!$K$2:$K$7677,E$19,Concepts_nodes!$L$2:$L$7677,$B29) -> 0 | F29: =COUNTIFS(Concepts_nodes!$K$2:$K$7677,F$19,Concepts_nodes!$L$2:$L$7677,$B29) -> 4 | G29: =COUNTIFS(Concepts_nodes!$K$2:$K$7677,G$19,Concepts_nodes!$L$2:$L$7677,$B29) -> 1 | H29: =COUNTIFS(Concepts_nodes!$K$2:$K$7677,H$19,Concepts_nodes!$L$2:$L$7677,$B29) -> 14 | I29: =COUNTIFS(Concepts_nodes!$K$2:$K$7677,I$19,Concepts_nodes!$L$2:$L$7677,$B29) -> 27 | J29: =COUNTIFS(Concepts_nodes!$K$2:$K$7677,J$19,Concepts_nodes!$L$2:$L$7677,$B29) -> 1 | ... L29: =COUNTIFS(Concepts_nodes!$K$2:$K$7677,L$19,Concepts_nodes!$L$2:$L$7677,$B29) -> 0
B30: Total | C30: =SUM(C20:L29) -> 7676 | D30: nodes in the sheet: | E30: =COUNTA(Concepts_nodes!A2:A7677) -> 7676 | F30: =IF(C30=E30,"✔ matches","✖ does not match") -> ✔ matches

Sheet Connectors
A1: Table of Connectors (10 × 10)
A2: Each cell shows how many words it has and the first ones (hand-made concepts first). Full list in the sheet Connectors_nodes. Position: x = (Lv − Gv)/2, y = (V − I)/2.
C4: ◄ Adaptation (You, structural) | H4: Imposition (I, Sensory) ►
C5: 1 | D5: 2 | E5: 3 | F5: 4 | G5: 5 | H5: 6 | I5: 7 | J5: 8 | K5: 9 | L5: 10
A6: Context (We, Possibility) ▲ | B6: 1 | F6: 4 if, so that, in order to, in order that | G6: 11 moreover, furthermore, besides, additionally, likewise, similarly … +5
B7: 2 | E7: 9 even if, provided (that), providing, as long as, so long as, in case … +3 | F7: 12 in a way, sort of, kind of, somewhat, a bit, more or less … +6 | J7: 1 fortunately
B8: 3 | D8: 4 first, to begin with, that (complementizer), & | E8: 5 then, next, afterwards, later, subsequently | K8: 8 indeed, in fact, actually, especially, certainly, as a matter of fact … +2
B9: 4 | D9: 17 and, also, too, plus, by the way, incidentally … +11 | E9: 3 or, either…or, alternatively | F9: 1 … | I9: 8 for example, for instance, such as, including, e.g., in particular … +2 | J9: 6 frankly, honestly, clearly, obviously, apparently, surprisingly
B10: 5 | C10: 1 " " | D10: 27 in other words, that is, i.e., to put it another way, although, even though … +21 | E10: 7 where, when (relative), why, ;, -, ( ) … +1 | I10: 3 meanwhile, at the same time, —
B11: 6 | D11: 16 but, on the other hand, in contrast, by contrast, whereas, while (contrast) … +10 | E11: 1 unless | K11: 1 !
B12: 7 | D12: 2 finally, lastly | E12: 3 instead, rather, or else | I12: 2 I mean, what I mean is
B13: 8 | D13: 7 in conclusion, to sum up, in short, in summary, overall, all in all … +1 | E13: 8 lest, for fear that, before, until, till, by the time … +2 | F13: 10 therefore, thus, hence, consequently, accordingly, as a result … +4
B14: 9 | F14: 15 except, except that, apart from, other than, but for, save … +9 | J14: 2 unfortunately, sadly
A15: World (That, logical) ▼ | B15: 10 | F15: 2 nor, neither…nor
A18: Count per cell (COUNTIFS formulas over Connectors_nodes)
C19: 1 | D19: 2 | E19: 3 | F19: 4 | G19: 5 | H19: 6 | I19: 7 | J19: 8 | K19: 9 | L19: 10
B20: 1 | C20: =COUNTIFS(Connectors_nodes!$K$2:$K$197,C$19,Connectors_nodes!$L$2:$L$197,$B20) -> 0 | D20: =COUNTIFS(Connectors_nodes!$K$2:$K$197,D$19,Connectors_nodes!$L$2:$L$197,$B20) -> 0 | E20: =COUNTIFS(Connectors_nodes!$K$2:$K$197,E$19,Connectors_nodes!$L$2:$L$197,$B20) -> 0 | F20: =COUNTIFS(Connectors_nodes!$K$2:$K$197,F$19,Connectors_nodes!$L$2:$L$197,$B20) -> 4 | G20: =COUNTIFS(Connectors_nodes!$K$2:$K$197,G$19,Connectors_nodes!$L$2:$L$197,$B20) -> 11 | H20: =COUNTIFS(Connectors_nodes!$K$2:$K$197,H$19,Connectors_nodes!$L$2:$L$197,$B20) -> 0 | I20: =COUNTIFS(Connectors_nodes!$K$2:$K$197,I$19,Connectors_nodes!$L$2:$L$197,$B20) -> 0 | J20: =COUNTIFS(Connectors_nodes!$K$2:$K$197,J$19,Connectors_nodes!$L$2:$L$197,$B20) -> 0 | ... L20: =COUNTIFS(Connectors_nodes!$K$2:$K$197,L$19,Connectors_nodes!$L$2:$L$197,$B20) -> 0
B21: 2 | C21: =COUNTIFS(Connectors_nodes!$K$2:$K$197,C$19,Connectors_nodes!$L$2:$L$197,$B21) -> 0 | D21: =COUNTIFS(Connectors_nodes!$K$2:$K$197,D$19,Connectors_nodes!$L$2:$L$197,$B21) -> 0 | E21: =COUNTIFS(Connectors_nodes!$K$2:$K$197,E$19,Connectors_nodes!$L$2:$L$197,$B21) -> 9 | F21: =COUNTIFS(Connectors_nodes!$K$2:$K$197,F$19,Connectors_nodes!$L$2:$L$197,$B21) -> 12 | G21: =COUNTIFS(Connectors_nodes!$K$2:$K$197,G$19,Connectors_nodes!$L$2:$L$197,$B21) -> 0 | H21: =COUNTIFS(Connectors_nodes!$K$2:$K$197,H$19,Connectors_nodes!$L$2:$L$197,$B21) -> 0 | I21: =COUNTIFS(Connectors_nodes!$K$2:$K$197,I$19,Connectors_nodes!$L$2:$L$197,$B21) -> 0 | J21: =COUNTIFS(Connectors_nodes!$K$2:$K$197,J$19,Connectors_nodes!$L$2:$L$197,$B21) -> 1 | ... L21: =COUNTIFS(Connectors_nodes!$K$2:$K$197,L$19,Connectors_nodes!$L$2:$L$197,$B21) -> 0
B22: 3 | C22: =COUNTIFS(Connectors_nodes!$K$2:$K$197,C$19,Connectors_nodes!$L$2:$L$197,$B22) -> 0 | D22: =COUNTIFS(Connectors_nodes!$K$2:$K$197,D$19,Connectors_nodes!$L$2:$L$197,$B22) -> 4 | E22: =COUNTIFS(Connectors_nodes!$K$2:$K$197,E$19,Connectors_nodes!$L$2:$L$197,$B22) -> 5 | F22: =COUNTIFS(Connectors_nodes!$K$2:$K$197,F$19,Connectors_nodes!$L$2:$L$197,$B22) -> 0 | G22: =COUNTIFS(Connectors_nodes!$K$2:$K$197,G$19,Connectors_nodes!$L$2:$L$197,$B22) -> 0 | H22: =COUNTIFS(Connectors_nodes!$K$2:$K$197,H$19,Connectors_nodes!$L$2:$L$197,$B22) -> 0 | I22: =COUNTIFS(Connectors_nodes!$K$2:$K$197,I$19,Connectors_nodes!$L$2:$L$197,$B22) -> 0 | J22: =COUNTIFS(Connectors_nodes!$K$2:$K$197,J$19,Connectors_nodes!$L$2:$L$197,$B22) -> 0 | ... L22: =COUNTIFS(Connectors_nodes!$K$2:$K$197,L$19,Connectors_nodes!$L$2:$L$197,$B22) -> 0
B23: 4 | C23: =COUNTIFS(Connectors_nodes!$K$2:$K$197,C$19,Connectors_nodes!$L$2:$L$197,$B23) -> 0 | D23: =COUNTIFS(Connectors_nodes!$K$2:$K$197,D$19,Connectors_nodes!$L$2:$L$197,$B23) -> 17 | E23: =COUNTIFS(Connectors_nodes!$K$2:$K$197,E$19,Connectors_nodes!$L$2:$L$197,$B23) -> 3 | F23: =COUNTIFS(Connectors_nodes!$K$2:$K$197,F$19,Connectors_nodes!$L$2:$L$197,$B23) -> 1 | G23: =COUNTIFS(Connectors_nodes!$K$2:$K$197,G$19,Connectors_nodes!$L$2:$L$197,$B23) -> 0 | H23: =COUNTIFS(Connectors_nodes!$K$2:$K$197,H$19,Connectors_nodes!$L$2:$L$197,$B23) -> 0 | I23: =COUNTIFS(Connectors_nodes!$K$2:$K$197,I$19,Connectors_nodes!$L$2:$L$197,$B23) -> 8 | J23: =COUNTIFS(Connectors_nodes!$K$2:$K$197,J$19,Connectors_nodes!$L$2:$L$197,$B23) -> 6 | ... L23: =COUNTIFS(Connectors_nodes!$K$2:$K$197,L$19,Connectors_nodes!$L$2:$L$197,$B23) -> 0
B24: 5 | C24: =COUNTIFS(Connectors_nodes!$K$2:$K$197,C$19,Connectors_nodes!$L$2:$L$197,$B24) -> 1 | D24: =COUNTIFS(Connectors_nodes!$K$2:$K$197,D$19,Connectors_nodes!$L$2:$L$197,$B24) -> 27 | E24: =COUNTIFS(Connectors_nodes!$K$2:$K$197,E$19,Connectors_nodes!$L$2:$L$197,$B24) -> 7 | F24: =COUNTIFS(Connectors_nodes!$K$2:$K$197,F$19,Connectors_nodes!$L$2:$L$197,$B24) -> 0 | G24: =COUNTIFS(Connectors_nodes!$K$2:$K$197,G$19,Connectors_nodes!$L$2:$L$197,$B24) -> 0 | H24: =COUNTIFS(Connectors_nodes!$K$2:$K$197,H$19,Connectors_nodes!$L$2:$L$197,$B24) -> 0 | I24: =COUNTIFS(Connectors_nodes!$K$2:$K$197,I$19,Connectors_nodes!$L$2:$L$197,$B24) -> 3 | J24: =COUNTIFS(Connectors_nodes!$K$2:$K$197,J$19,Connectors_nodes!$L$2:$L$197,$B24) -> 0 | ... L24: =COUNTIFS(Connectors_nodes!$K$2:$K$197,L$19,Connectors_nodes!$L$2:$L$197,$B24) -> 0
B25: 6 | C25: =COUNTIFS(Connectors_nodes!$K$2:$K$197,C$19,Connectors_nodes!$L$2:$L$197,$B25) -> 0 | D25: =COUNTIFS(Connectors_nodes!$K$2:$K$197,D$19,Connectors_nodes!$L$2:$L$197,$B25) -> 16 | E25: =COUNTIFS(Connectors_nodes!$K$2:$K$197,E$19,Connectors_nodes!$L$2:$L$197,$B25) -> 1 | F25: =COUNTIFS(Connectors_nodes!$K$2:$K$197,F$19,Connectors_nodes!$L$2:$L$197,$B25) -> 0 | G25: =COUNTIFS(Connectors_nodes!$K$2:$K$197,G$19,Connectors_nodes!$L$2:$L$197,$B25) -> 0 | H25: =COUNTIFS(Connectors_nodes!$K$2:$K$197,H$19,Connectors_nodes!$L$2:$L$197,$B25) -> 0 | I25: =COUNTIFS(Connectors_nodes!$K$2:$K$197,I$19,Connectors_nodes!$L$2:$L$197,$B25) -> 0 | J25: =COUNTIFS(Connectors_nodes!$K$2:$K$197,J$19,Connectors_nodes!$L$2:$L$197,$B25) -> 0 | ... L25: =COUNTIFS(Connectors_nodes!$K$2:$K$197,L$19,Connectors_nodes!$L$2:$L$197,$B25) -> 0
B26: 7 | C26: =COUNTIFS(Connectors_nodes!$K$2:$K$197,C$19,Connectors_nodes!$L$2:$L$197,$B26) -> 0 | D26: =COUNTIFS(Connectors_nodes!$K$2:$K$197,D$19,Connectors_nodes!$L$2:$L$197,$B26) -> 2 | E26: =COUNTIFS(Connectors_nodes!$K$2:$K$197,E$19,Connectors_nodes!$L$2:$L$197,$B26) -> 3 | F26: =COUNTIFS(Connectors_nodes!$K$2:$K$197,F$19,Connectors_nodes!$L$2:$L$197,$B26) -> 0 | G26: =COUNTIFS(Connectors_nodes!$K$2:$K$197,G$19,Connectors_nodes!$L$2:$L$197,$B26) -> 0 | H26: =COUNTIFS(Connectors_nodes!$K$2:$K$197,H$19,Connectors_nodes!$L$2:$L$197,$B26) -> 0 | I26: =COUNTIFS(Connectors_nodes!$K$2:$K$197,I$19,Connectors_nodes!$L$2:$L$197,$B26) -> 2 | J26: =COUNTIFS(Connectors_nodes!$K$2:$K$197,J$19,Connectors_nodes!$L$2:$L$197,$B26) -> 0 | ... L26: =COUNTIFS(Connectors_nodes!$K$2:$K$197,L$19,Connectors_nodes!$L$2:$L$197,$B26) -> 0
B27: 8 | C27: =COUNTIFS(Connectors_nodes!$K$2:$K$197,C$19,Connectors_nodes!$L$2:$L$197,$B27) -> 0 | D27: =COUNTIFS(Connectors_nodes!$K$2:$K$197,D$19,Connectors_nodes!$L$2:$L$197,$B27) -> 7 | E27: =COUNTIFS(Connectors_nodes!$K$2:$K$197,E$19,Connectors_nodes!$L$2:$L$197,$B27) -> 8 | F27: =COUNTIFS(Connectors_nodes!$K$2:$K$197,F$19,Connectors_nodes!$L$2:$L$197,$B27) -> 10 | G27: =COUNTIFS(Connectors_nodes!$K$2:$K$197,G$19,Connectors_nodes!$L$2:$L$197,$B27) -> 0 | H27: =COUNTIFS(Connectors_nodes!$K$2:$K$197,H$19,Connectors_nodes!$L$2:$L$197,$B27) -> 0 | I27: =COUNTIFS(Connectors_nodes!$K$2:$K$197,I$19,Connectors_nodes!$L$2:$L$197,$B27) -> 0 | J27: =COUNTIFS(Connectors_nodes!$K$2:$K$197,J$19,Connectors_nodes!$L$2:$L$197,$B27) -> 0 | ... L27: =COUNTIFS(Connectors_nodes!$K$2:$K$197,L$19,Connectors_nodes!$L$2:$L$197,$B27) -> 0
B28: 9 | C28: =COUNTIFS(Connectors_nodes!$K$2:$K$197,C$19,Connectors_nodes!$L$2:$L$197,$B28) -> 0 | D28: =COUNTIFS(Connectors_nodes!$K$2:$K$197,D$19,Connectors_nodes!$L$2:$L$197,$B28) -> 0 | E28: =COUNTIFS(Connectors_nodes!$K$2:$K$197,E$19,Connectors_nodes!$L$2:$L$197,$B28) -> 0 | F28: =COUNTIFS(Connectors_nodes!$K$2:$K$197,F$19,Connectors_nodes!$L$2:$L$197,$B28) -> 15 | G28: =COUNTIFS(Connectors_nodes!$K$2:$K$197,G$19,Connectors_nodes!$L$2:$L$197,$B28) -> 0 | H28: =COUNTIFS(Connectors_nodes!$K$2:$K$197,H$19,Connectors_nodes!$L$2:$L$197,$B28) -> 0 | I28: =COUNTIFS(Connectors_nodes!$K$2:$K$197,I$19,Connectors_nodes!$L$2:$L$197,$B28) -> 0 | J28: =COUNTIFS(Connectors_nodes!$K$2:$K$197,J$19,Connectors_nodes!$L$2:$L$197,$B28) -> 2 | ... L28: =COUNTIFS(Connectors_nodes!$K$2:$K$197,L$19,Connectors_nodes!$L$2:$L$197,$B28) -> 0
B29: 10 | C29: =COUNTIFS(Connectors_nodes!$K$2:$K$197,C$19,Connectors_nodes!$L$2:$L$197,$B29) -> 0 | D29: =COUNTIFS(Connectors_nodes!$K$2:$K$197,D$19,Connectors_nodes!$L$2:$L$197,$B29) -> 0 | E29: =COUNTIFS(Connectors_nodes!$K$2:$K$197,E$19,Connectors_nodes!$L$2:$L$197,$B29) -> 0 | F29: =COUNTIFS(Connectors_nodes!$K$2:$K$197,F$19,Connectors_nodes!$L$2:$L$197,$B29) -> 2 | G29: =COUNTIFS(Connectors_nodes!$K$2:$K$197,G$19,Connectors_nodes!$L$2:$L$197,$B29) -> 0 | H29: =COUNTIFS(Connectors_nodes!$K$2:$K$197,H$19,Connectors_nodes!$L$2:$L$197,$B29) -> 0 | I29: =COUNTIFS(Connectors_nodes!$K$2:$K$197,I$19,Connectors_nodes!$L$2:$L$197,$B29) -> 0 | J29: =COUNTIFS(Connectors_nodes!$K$2:$K$197,J$19,Connectors_nodes!$L$2:$L$197,$B29) -> 0 | ... L29: =COUNTIFS(Connectors_nodes!$K$2:$K$197,L$19,Connectors_nodes!$L$2:$L$197,$B29) -> 0
B30: Total | C30: =SUM(C20:L29) -> 196 | D30: nodes in the sheet: | E30: =COUNTA(Connectors_nodes!A2:A197) -> 196 | F30: =IF(C30=E30,"✔ matches","✖ does not match") -> ✔ matches

Sheet Subjects_nodes
A1: Word | B1: Type | C1: Category | D1: Subtype | E1: V | F1: I | G1: Lv | H1: Gv | I1: x | J1: y | K1: Col | L1: Row | M1: τ | N1: Source | O1: Sent+ | P1: Sent− | Q1: Synonyms | R1: Related (nodes) | S1: Related (labels without a node) | T1: Related (WordNet) | U1: Related (manual) | V1: Opposites
A2: children | B2: biological | C2: person | E2: 9 | F2: 1 | G2: 1 | H2: 10 | I2: =(G2-H2)/2 -> -4.5 | J2: =(E2-F2)/2 -> 4 | K2: =MAX(1,MIN(10,ROUNDUP(I2+5,0))) -> 1 | L2: =MAX(1,MIN(10,ROUNDUP(5-J2,0))) -> 1 | M2: =MIN(E2,F2) -> 1 | N2: lexicon | O2: 0.04 | P2: 0 | Q2: child, fry, kid, minor, nestling, nipper | T2: juvenile (is-a), orphan (kind-of), imp (kind-of), monkey (kind-of), young (definition), sex (definition), issue (is-a), family (part), human (definition), son (definition)
A3: members | B3: biological | C3: person | E3: 9 | F3: 1 | G3: 1 | H3: 10 | I3: =(G3-H3)/2 -> -4.5 | J3: =(E3-F3)/2 -> 4 | K3: =MAX(1,MIN(10,ROUNDUP(I3+5,0))) -> 1 | L3: =MAX(1,MIN(10,ROUNDUP(5-J3,0))) -> 1 | M3: =MIN(E3,F3) -> 1 | N3: lexicon | O3: 0 | P3: 0 | Q3: fellow member, member | T3: associate (is-a), brother (kind-of), commissioner (kind-of), conservative (kind-of), person (definition), social (definition), group (definition), individual (definition), part (is-a), portion (is-a)
A4: child | B4: biological | C4: person | E4: 9 | F4: 1 | G4: 1 | H4: 10 | I4: =(G4-H4)/2 -> -4.5 | J4: =(E4-F4)/2 -> 4 | K4: =MAX(1,MIN(10,ROUNDUP(I4+5,0))) -> 1 | L4: =MAX(1,MIN(10,ROUNDUP(5-J4,0))) -> 1 | M4: =MIN(E4,F4) -> 1 | N4: lexicon | O4: 0.04 | P4: 0 | Q4: fry, kid, minor, nestling, nipper | T4: juvenile (is-a), orphan (kind-of), imp (kind-of), monkey (kind-of), childhood (derived), young (definition), sex (definition), issue (is-a), family (part), human (definition), son (definition) | U4: play, jump, run, laugh, story, family, mother, father, dog, sing, dance, sleep, climb, swim, cry | V4: parent
A5: kids | B5: biological | C5: person | E5: 9 | F5: 1 | G5: 1 | H5: 10 | I5: =(G5-H5)/2 -> -4.5 | J5: =(E5-F5)/2 -> 4 | K5: =MAX(1,MIN(10,ROUNDUP(I5+5,0))) -> 1 | L5: =MAX(1,MIN(10,ROUNDUP(5-J5,0))) -> 1 | M5: =MIN(E5,F5) -> 1 | N5: lexicon | O5: 0 | P5: 0 | Q5: child, fry, kid, minor, nestling, nipper | T5: juvenile (is-a), orphan (kind-of), imp (kind-of), monkey (kind-of), young (definition), sex (definition), leather (is-a), soft (definition), smooth (definition)
A6: son | B6: biological | C6: person | E6: 9 | F6: 1 | G6: 1 | H6: 10 | I6: =(G6-H6)/2 -> -4.5 | J6: =(E6-F6)/2 -> 4 | K6: =MAX(1,MIN(10,ROUNDUP(I6+5,0))) -> 1 | L6: =MAX(1,MIN(10,ROUNDUP(5-J6,0))) -> 1 | M6: =MIN(E6,F6) -> 1 | N6: lexicon | O6: 0 | P6: 0 | Q6: boy | T6: junior (kind-of), male (definition), human (definition), divine (definition), word (definition) | V6: daughter
A7: baby | B7: biological | C7: person | E7: 9 | F7: 1 | G7: 1 | H7: 10 | I7: =(G7-H7)/2 -> -4.5 | J7: =(E7-F7)/2 -> 4 | K7: =MAX(1,MIN(10,ROUNDUP(I7+5,0))) -> 1 | L7: =MAX(1,MIN(10,ROUNDUP(5-J7,0))) -> 1 | M7: =MIN(E7,F7) -> 1 | N7: lexicon | O7: 0 | P7: 0 | Q7: babe, infant | T7: child (is-a), kid (is-a), newborn (kind-of), young (definition), birth (definition), year (definition), begin (definition), issue (is-a)
A8: wife | B8: biological | C8: person | E8: 9 | F8: 1 | G8: 1 | H8: 10 | I8: =(G8-H8)/2 -> -4.5 | J8: =(E8-F8)/2 -> 4 | K8: =MAX(1,MIN(10,ROUNDUP(I8+5,0))) -> 1 | L8: =MAX(1,MIN(10,ROUNDUP(5-J8,0))) -> 1 | M8: =MIN(E8,F8) -> 1 | N8: lexicon | O8: 0 | P8: 0 | Q8: married woman | T8: woman (is-a), partner (is-a), spouse (is-a), married (definition), man (definition), marriage (definition) | V8: husband
A9: parents | B9: biological | C9: person | E9: 9 | F9: 1 | G9: 1 | H9: 10 | I9: =(G9-H9)/2 -> -4.5 | J9: =(E9-F9)/2 -> 4 | K9: =MAX(1,MIN(10,ROUNDUP(I9+5,0))) -> 1 | L9: =MAX(1,MIN(10,ROUNDUP(5-J9,0))) -> 1 | M9: =MIN(E9,F9) -> 1 | N9: lexicon | O9: 0 | P9: 0 | Q9: parent | T9: mother (kind-of), father (kind-of), family (part), give (definition), birth (definition), raise (definition), child (definition), being (is-a)
A10: member | B10: biological | C10: person | E10: 9 | F10: 1 | G10: 1 | H10: 10 | I10: =(G10-H10)/2 -> -4.5 | J10: =(E10-F10)/2 -> 4 | K10: =MAX(1,MIN(10,ROUNDUP(I10+5,0))) -> 1 | L10: =MAX(1,MIN(10,ROUNDUP(5-J10,0))) -> 1 | M10: =MIN(E10,F10) -> 1 | N10: lexicon | O10: 0 | P10: 0 | Q10: fellow member | T10: associate (is-a), brother (kind-of), commissioner (kind-of), conservative (kind-of), membership (derived), person (definition), social (definition), group (definition), individual (definition), part (is-a), portion (is-a)
A11: mom | B11: biological | C11: person | E11: 10 | F11: 1 | G11: 1 | H11: 10 | I11: =(G11-H11)/2 -> -4.5 | J11: =(E11-F11)/2 -> 4.5 | K11: =MAX(1,MIN(10,ROUNDUP(I11+5,0))) -> 1 | L11: =MAX(1,MIN(10,ROUNDUP(5-J11,0))) -> 1 | M11: =MIN(E11,F11) -> 1 | N11: lexicon | O11: 0.88 | P11: 0 | Q11: ma, mama, mamma, mammy, momma | T11: mother (is-a), informal (definition), terms (definition)
A12: brother | B12: biological | C12: person | E12: 9 | F12: 1 | G12: 1 | H12: 10 | I12: =(G12-H12)/2 -> -4.5 | J12: =(E12-F12)/2 -> 4 | K12: =MAX(1,MIN(10,ROUNDUP(I12+5,0))) -> 1 | L12: =MAX(1,MIN(10,ROUNDUP(5-J12,0))) -> 1 | M12: =MIN(E12,F12) -> 1 | N12: lexicon | O12: 0.04 | P12: 0 | Q12: blood brother | T12: male (definition), parent (definition), member (is-a), mason (kind-of), brotherhood (part), fellow (definition), religion (definition) | V12: sister
A13: daughter | B13: biological | C13: person | E13: 9 | F13: 1 | G13: 1 | H13: 10 | I13: =(G13-H13)/2 -> -4.5 | J13: =(E13-F13)/2 -> 4 | K13: =MAX(1,MIN(10,ROUNDUP(I13+5,0))) -> 1 | L13: =MAX(1,MIN(10,ROUNDUP(5-J13,0))) -> 1 | M13: =MIN(E13,F13) -> 1 | N13: lexicon | O13: 0 | P13: 0 | Q13: girl | T13: female (definition), human (definition) | V13: son
A14: husband | B14: biological | C14: person | E14: 9 | F14: 1 | G14: 1 | H14: 10 | I14: =(G14-H14)/2 -> -4.5 | J14: =(E14-F14)/2 -> 4 | K14: =MAX(1,MIN(10,ROUNDUP(I14+5,0))) -> 1 | L14: =MAX(1,MIN(10,ROUNDUP(5-J14,0))) -> 1 | M14: =MIN(E14,F14) -> 1 | N14: lexicon | O14: 0 | P14: 0 | Q14: hubby, married man | T14: partner (is-a), spouse (is-a), mate (is-a), married (definition), man (definition), woman (definition), marriage (definition) | V14: wife
A15: kid | B15: biological | C15: person | E15: 9 | F15: 1 | G15: 1 | H15: 10 | I15: =(G15-H15)/2 -> -4.5 | J15: =(E15-F15)/2 -> 4 | K15: =MAX(1,MIN(10,ROUNDUP(I15+5,0))) -> 1 | L15: =MAX(1,MIN(10,ROUNDUP(5-J15,0))) -> 1 | M15: =MIN(E15,F15) -> 1 | N15: lexicon | O15: 0 | P15: 0 | Q15: child, fry, minor, nestling, nipper | T15: juvenile (is-a), orphan (kind-of), imp (kind-of), monkey (kind-of), young (definition), sex (definition), leather (is-a), soft (definition), smooth (definition)
A16: dad | B16: biological | C16: person | E16: 9 | F16: 1 | G16: 1 | H16: 10 | I16: =(G16-H16)/2 -> -4.5 | J16: =(E16-F16)/2 -> 4 | K16: =MAX(1,MIN(10,ROUNDUP(I16+5,0))) -> 1 | L16: =MAX(1,MIN(10,ROUNDUP(5-J16,0))) -> 1 | M16: =MIN(E16,F16) -> 1 | N16: lexicon | O16: 0 | P16: 0 | Q16: dada, daddy, pa, papa, pappa | T16: father (is-a), informal (definition), term (definition), probably (definition), baby (definition)
A17: sister | B17: biological | C17: person | E17: 9 | F17: 1 | G17: 1 | H17: 10 | I17: =(G17-H17)/2 -> -4.5 | J17: =(E17-F17)/2 -> 4 | K17: =MAX(1,MIN(10,ROUNDUP(I17+5,0))) -> 1 | L17: =MAX(1,MIN(10,ROUNDUP(5-J17,0))) -> 1 | M17: =MIN(E17,F17) -> 1 | N17: lexicon | O17: 0 | P17: 0 | Q17: sis | T17: female (definition), parent (definition), nun (is-a), roman (definition), catholic (definition) | V17: brother
A18: master | B18: biological | C18: person | E18: 10 | F18: 1 | G18: 2 | H18: 10 | I18: =(G18-H18)/2 -> -4 | J18: =(E18-F18)/2 -> 4.5 | K18: =MAX(1,MIN(10,ROUNDUP(I18+5,0))) -> 1 | L18: =MAX(1,MIN(10,ROUNDUP(5-J18,0))) -> 1 | M18: =MIN(E18,F18) -> 1 | N18: lexicon | O18: 0.29 | P18: 0 | Q18: maestro | T18: artist (is-a), skill (definition), ruler (is-a), general (definition), authority (definition)
A19: pop | B19: biological | C19: person | E19: 9 | F19: 1 | G19: 1 | H19: 10 | I19: =(G19-H19)/2 -> -4.5 | J19: =(E19-F19)/2 -> 4 | K19: =MAX(1,MIN(10,ROUNDUP(I19+5,0))) -> 1 | L19: =MAX(1,MIN(10,ROUNDUP(5-J19,0))) -> 1 | M19: =MIN(E19,F19) -> 1 | N19: lexicon | O19: 0 | P19: 0 | Q19: dad, dada, daddy, pa, papa, pappa | T19: father (is-a), informal (definition), term (definition), probably (definition), baby (definition)
A20: partner | B20: biological | C20: person | E20: 9 | F20: 1 | G20: 1 | H20: 10 | I20: =(G20-H20)/2 -> -4.5 | J20: =(E20-F20)/2 -> 4 | K20: =MAX(1,MIN(10,ROUNDUP(I20+5,0))) -> 1 | L20: =MAX(1,MIN(10,ROUNDUP(5-J20,0))) -> 1 | M20: =MIN(E20,F20) -> 1 | N20: lexicon | O20: 0 | P20: 0 | Q20: better half, married person, mate, spouse | T20: relative (is-a), relation (is-a), wife (kind-of), husband (kind-of), marriage (part), associate (is-a), partnership (derived), activity (definition), sphere (definition), common (definition), interest (definition)
A21: youth | B21: biological | C21: person | E21: 9 | F21: 1 | G21: 1 | H21: 10 | I21: =(G21-H21)/2 -> -4.5 | J21: =(E21-F21)/2 -> 4 | K21: =MAX(1,MIN(10,ROUNDUP(I21+5,0))) -> 1 | L21: =MAX(1,MIN(10,ROUNDUP(5-J21,0))) -> 1 | M21: =MIN(E21,F21) -> 1 | N21: lexicon | O21: 0 | P21: 0 | Q21: spring chicken, young person, younker | T21: juvenile (is-a), blade (kind-of), pupil (kind-of), puppy (kind-of), young (definition), man (definition), boy (definition), collectively (definition)
A22: brothers | B22: biological | C22: person | E22: 9 | F22: 1 | G22: 1 | H22: 10 | I22: =(G22-H22)/2 -> -4.5 | J22: =(E22-F22)/2 -> 4 | K22: =MAX(1,MIN(10,ROUNDUP(I22+5,0))) -> 1 | L22: =MAX(1,MIN(10,ROUNDUP(5-J22,0))) -> 1 | M22: =MIN(E22,F22) -> 1 | N22: lexicon | O22: 0.04 | P22: 0 | Q22: blood brother, brother | T22: male (definition), parent (definition), member (is-a), mason (kind-of), brotherhood (part), fellow (definition), religion (definition)
A23: ma | B23: biological | C23: person | E23: 10 | F23: 1 | G23: 1 | H23: 10 | I23: =(G23-H23)/2 -> -4.5 | J23: =(E23-F23)/2 -> 4.5 | K23: =MAX(1,MIN(10,ROUNDUP(I23+5,0))) -> 1 | L23: =MAX(1,MIN(10,ROUNDUP(5-J23,0))) -> 1 | M23: =MIN(E23,F23) -> 1 | N23: lexicon | O23: 0.29 | P23: 0.04 | Q23: mama, mamma, mammy, mom, momma | T23: mother (is-a), informal (definition), terms (definition), master (definition), degree (definition)
A24: parent | B24: biological | C24: person | E24: 9 | F24: 1 | G24: 1 | H24: 10 | I24: =(G24-H24)/2 -> -4.5 | J24: =(E24-F24)/2 -> 4 | K24: =MAX(1,MIN(10,ROUNDUP(I24+5,0))) -> 1 | L24: =MAX(1,MIN(10,ROUNDUP(5-J24,0))) -> 1 | M24: =MIN(E24,F24) -> 1 | N24: lexicon | O24: 0 | P24: 0 | T24: mother (kind-of), father (kind-of), family (part), parental (derived), give (definition), birth (definition), raise (definition), child (definition), being (is-a) | V24: child
A25: partners | B25: biological | C25: person | E25: 9 | F25: 1 | G25: 1 | H25: 10 | I25: =(G25-H25)/2 -> -4.5 | J25: =(E25-F25)/2 -> 4 | K25: =MAX(1,MIN(10,ROUNDUP(I25+5,0))) -> 1 | L25: =MAX(1,MIN(10,ROUNDUP(5-J25,0))) -> 1 | M25: =MIN(E25,F25) -> 1 | N25: lexicon | O25: 0 | P25: 0 | Q25: better half, married person, mate, partner, spouse | T25: relative (is-a), relation (is-a), wife (kind-of), husband (kind-of), marriage (part), partner (definition), associate (is-a), activity (definition), sphere (definition), common (definition)
A26: sons | B26: biological | C26: person | E26: 9 | F26: 1 | G26: 1 | H26: 10 | I26: =(G26-H26)/2 -> -4.5 | J26: =(E26-F26)/2 -> 4 | K26: =MAX(1,MIN(10,ROUNDUP(I26+5,0))) -> 1 | L26: =MAX(1,MIN(10,ROUNDUP(5-J26,0))) -> 1 | M26: =MIN(E26,F26) -> 1 | N26: lexicon | O26: 0 | P26: 0 | Q26: boy, son | T26: junior (kind-of), male (definition), human (definition), divine (definition), word (definition)
A27: pa | B27: biological | C27: person | E27: 9 | F27: 1 | G27: 1 | H27: 10 | I27: =(G27-H27)/2 -> -4.5 | J27: =(E27-F27)/2 -> 4 | K27: =MAX(1,MIN(10,ROUNDUP(I27+5,0))) -> 1 | L27: =MAX(1,MIN(10,ROUNDUP(5-J27,0))) -> 1 | M27: =MIN(E27,F27) -> 1 | N27: lexicon | O27: 0 | P27: 0 | Q27: dad, dada, daddy, papa, pappa | T27: father (is-a), informal (definition), term (definition), probably (definition), baby (definition), metal (is-a)
A28: babies | B28: biological | C28: person | E28: 9 | F28: 1 | G28: 1 | H28: 10 | I28: =(G28-H28)/2 -> -4.5 | J28: =(E28-F28)/2 -> 4 | K28: =MAX(1,MIN(10,ROUNDUP(I28+5,0))) -> 1 | L28: =MAX(1,MIN(10,ROUNDUP(5-J28,0))) -> 1 | M28: =MIN(E28,F28) -> 1 | N28: lexicon | O28: 0 | P28: 0 | Q28: babe, baby, infant | T28: child (is-a), kid (is-a), newborn (kind-of), young (definition), birth (definition), year (definition), begin (definition), issue (is-a)
A29: uncle | B29: biological | C29: person | E29: 9 | F29: 1 | G29: 1 | H29: 10 | I29: =(G29-H29)/2 -> -4.5 | J29: =(E29-F29)/2 -> 4 | K29: =MAX(1,MIN(10,ROUNDUP(I29+5,0))) -> 1 | L29: =MAX(1,MIN(10,ROUNDUP(5-J29,0))) -> 1 | M29: =MIN(E29,F29) -> 1 | N29: lexicon | O29: 0 | P29: 0 | T29: brother (definition), father (definition), mother (definition), husband (definition) | V29: aunt
A30: sisters | B30: biological | C30: person | E30: 9 | F30: 1 | G30: 1 | H30: 10 | I30: =(G30-H30)/2 -> -4.5 | J30: =(E30-F30)/2 -> 4 | K30: =MAX(1,MIN(10,ROUNDUP(I30+5,0))) -> 1 | L30: =MAX(1,MIN(10,ROUNDUP(5-J30,0))) -> 1 | M30: =MIN(E30,F30) -> 1 | N30: lexicon | O30: 0 | P30: 0 | Q30: sis, sister | T30: female (definition), parent (definition), nun (is-a), roman (definition), catholic (definition)
A31: cousin | B31: biological | C31: person | E31: 9 | F31: 1 | G31: 1 | H31: 10 | I31: =(G31-H31)/2 -> -4.5 | J31: =(E31-F31)/2 -> 4 | K31: =MAX(1,MIN(10,ROUNDUP(I31+5,0))) -> 1 | L31: =MAX(1,MIN(10,ROUNDUP(5-J31,0))) -> 1 | M31: =MIN(E31,F31) -> 1 | N31: lexicon | O31: 0 | P31: 0 | Q31: cousin-german, first cousin, full cousin | T31: relative (is-a), relation (is-a), child (definition), aunt (definition), uncle (definition)
A32: buddy | B32: biological | C32: person | E32: 10 | F32: 1 | G32: 1 | H32: 10 | I32: =(G32-H32)/2 -> -4.5 | J32: =(E32-F32)/2 -> 4.5 | K32: =MAX(1,MIN(10,ROUNDUP(I32+5,0))) -> 1 | L32: =MAX(1,MIN(10,ROUNDUP(5-J32,0))) -> 1 | M32: =MIN(E32,F32) -> 1 | N32: lexicon | O32: 0.12 | P32: 0 | Q32: brother, chum, crony, pal, sidekick | T32: friend (is-a), close (definition), accompany (definition), activity (definition)
A33: participants | B33: biological | C33: person | E33: 9 | F33: 1 | G33: 1 | H33: 10 | I33: =(G33-H33)/2 -> -4.5 | J33: =(E33-F33)/2 -> 4 | K33: =MAX(1,MIN(10,ROUNDUP(I33+5,0))) -> 1 | L33: =MAX(1,MIN(10,ROUNDUP(5-J33,0))) -> 1 | M33: =MIN(E33,F33) -> 1 | N33: lexicon | O33: 0 | P33: 0 | Q33: participant | T33: associate (is-a), bride (kind-of), player (kind-of), take (definition), part (definition), activity (definition), mvp (kind-of), participate (definition)
A34: critics | B34: biological | C34: person | E34: 9 | F34: 1 | G34: 2 | H34: 10 | I34: =(G34-H34)/2 -> -4 | J34: =(E34-F34)/2 -> 4 | K34: =MAX(1,MIN(10,ROUNDUP(I34+5,0))) -> 1 | L34: =MAX(1,MIN(10,ROUNDUP(5-J34,0))) -> 1 | M34: =MIN(E34,F34) -> 1 | N34: lexicon | O34: 0.12 | P34: 0.04 | Q34: critic | T34: professional (is-a), engage (definition), analysis (definition), interpretation (definition), works (definition), judge (is-a), reader (kind-of), referee (kind-of)
A35: daddy | B35: biological | C35: person | E35: 9 | F35: 1 | G35: 1 | H35: 10 | I35: =(G35-H35)/2 -> -4.5 | J35: =(E35-F35)/2 -> 4 | K35: =MAX(1,MIN(10,ROUNDUP(I35+5,0))) -> 1 | L35: =MAX(1,MIN(10,ROUNDUP(5-J35,0))) -> 1 | M35: =MIN(E35,F35) -> 1 | N35: lexicon | O35: 0 | P35: 0 | Q35: dad, dada, pa, papa, pappa | T35: father (is-a), informal (definition), term (definition), probably (definition), baby (definition)
A36: twin | B36: biological | C36: person | E36: 9 | F36: 1 | G36: 1 | H36: 10 | I36: =(G36-H36)/2 -> -4.5 | J36: =(E36-F36)/2 -> 4 | K36: =MAX(1,MIN(10,ROUNDUP(I36+5,0))) -> 1 | L36: =MAX(1,MIN(10,ROUNDUP(5-J36,0))) -> 1 | M36: =MIN(E36,F36) -> 1 | N36: lexicon | O36: 0 | P36: 0 | Q36: Gemini, Twin Falls | T36: born (definition), time (definition), pregnancy (definition), person (is-a), individual (is-a), someone (is-a), sun (definition)
A37: genius | B37: biological | C37: person | E37: 10 | F37: 1 | G37: 2 | H37: 10 | I37: =(G37-H37)/2 -> -4 | J37: =(E37-F37)/2 -> 4.5 | K37: =MAX(1,MIN(10,ROUNDUP(I37+5,0))) -> 1 | L37: =MAX(1,MIN(10,ROUNDUP(5-J37,0))) -> 1 | M37: =MIN(E37,F37) -> 1 | N37: lexicon | O37: 0.46 | P37: 0 | Q37: Einstein, brain, brainiac, mastermind | T37: intellectual (is-a), exceptional (definition), ability (definition), intelligence (is-a), unusual (definition), mental (definition)
A38: teen | B38: biological | C38: person | E38: 9 | F38: 1 | G38: 1 | H38: 10 | I38: =(G38-H38)/2 -> -4.5 | J38: =(E38-F38)/2 -> 4 | K38: =MAX(1,MIN(10,ROUNDUP(I38+5,0))) -> 1 | L38: =MAX(1,MIN(10,ROUNDUP(5-J38,0))) -> 1 | M38: =MIN(E38,F38) -> 1 | N38: lexicon | O38: 0 | P38: 0 | Q38: adolescent, stripling, teenager | T38: juvenile (is-a), punk (kind-of), maturity (definition)
A39: mothers | B39: biological | C39: person | E39: 9 | F39: 1 | G39: 1 | H39: 10 | I39: =(G39-H39)/2 -> -4.5 | J39: =(E39-F39)/2 -> 4 | K39: =MAX(1,MIN(10,ROUNDUP(I39+5,0))) -> 1 | L39: =MAX(1,MIN(10,ROUNDUP(5-J39,0))) -> 1 | M39: =MIN(E39,F39) -> 1 | N39: lexicon | O39: 0 | P39: 0 | Q39: female parent, mother | T39: parent (is-a), ma (kind-of), mama (kind-of), mommy (kind-of), woman (definition), given (definition), birth (definition), child (definition)
A40: colleagues | B40: biological | C40: person | E40: 9 | F40: 1 | G40: 1 | H40: 10 | I40: =(G40-H40)/2 -> -4.5 | J40: =(E40-F40)/2 -> 4 | K40: =MAX(1,MIN(10,ROUNDUP(I40+5,0))) -> 1 | L40: =MAX(1,MIN(10,ROUNDUP(5-J40,0))) -> 1 | M40: =MIN(E40,F40) -> 1 | N40: lexicon | O40: 0 | P40: 0.06 | Q40: co-worker, colleague, fellow worker, workfellow | T40: associate (is-a), works (definition), member (definition), class (definition), profession (definition)
...

Sheet Concepts_nodes
A1: Word | B1: Type | C1: Category | D1: Subtype | E1: V | F1: I | G1: Lv | H1: Gv | I1: x | J1: y | K1: Col | L1: Row | M1: τ | N1: Source | O1: Sent+ | P1: Sent− | Q1: Synonyms | R1: Related (nodes) | S1: Related (labels without a node) | T1: Related (WordNet) | U1: Related (manual) | V1: Opposites
A2: excellent | B2: quality | C2: quality | D2: evaluative | E2: 9 | F2: 1 | G2: 1 | H2: 9 | I2: =(G2-H2)/2 -> -4 | J2: =(E2-F2)/2 -> 4 | K2: =MAX(1,MIN(10,ROUNDUP(I2+5,0))) -> 1 | L2: =MAX(1,MIN(10,ROUNDUP(5-J2,0))) -> 1 | M2: =MIN(E2,F2) -> 1 | N2: lexicon | O2: 1 | P2: 0 | Q2: fantabulous, first-class, splendid | T2: superior (similar), excellence (derived), good (definition), high (definition), quality (definition) | V2: inferior
A3: dream | B3: non_biological | C3: cognition | E3: 10 | F3: 2 | G3: 3 | H3: 8 | I3: =(G3-H3)/2 -> -2.5 | J3: =(E3-F3)/2 -> 4 | K3: =MAX(1,MIN(10,ROUNDUP(I3+5,0))) -> 3 | L3: =MAX(1,MIN(10,ROUNDUP(5-J3,0))) -> 1 | M3: =MIN(E3,F3) -> 2 | N3: lexicon | O3: 0.29 | P3: 0.08 | Q3: dreaming | T3: imagination (is-a), imagery (is-a), imaging (is-a), nightmare (kind-of), sleeping (part), series (definition), mental (definition), image (definition), emotion (definition) | U3: sleep, night, hope, fear, story
A4: passion | B4: non_biological | C4: emotion | E4: 9 | F4: 1 | G4: 8 | H4: 2 | I4: =(G4-H4)/2 -> 3 | J4: =(E4-F4)/2 -> 4 | K4: =MAX(1,MIN(10,ROUNDUP(I4+5,0))) -> 8 | L4: =MAX(1,MIN(10,ROUNDUP(5-J4,0))) -> 1 | M4: =MIN(E4,F4) -> 1 | N4: concept+lexicon | O4: 0.54 | P4: 0.04 | Q4: passionateness | R4: self | T4: feeling (is-a), fire (kind-of), abandon (kind-of), strong (definition), emotion (definition), emotional (definition)
A5: favour | B5: non_biological | C5: emotion | E5: 9 | F5: 1 | G5: 8 | H5: 2 | I5: =(G5-H5)/2 -> 3 | J5: =(E5-F5)/2 -> 4 | K5: =MAX(1,MIN(10,ROUNDUP(I5+5,0))) -> 8 | L5: =MAX(1,MIN(10,ROUNDUP(5-J5,0))) -> 1 | M5: =MIN(E5,F5) -> 1 | N5: concept+lexicon | O5: 0.46 | P5: 0.04 | Q5: favor | R5: self | T5: approval (is-a), feeling (definition), favorable (definition), regard (definition), tendency (is-a), approve (definition)
A6: desired | B6: non_biological | C6: emotion | D6: emotion | E6: 9 | F6: 1 | G6: 8 | H6: 2 | I6: =(G6-H6)/2 -> 3 | J6: =(E6-F6)/2 -> 4 | K6: =MAX(1,MIN(10,ROUNDUP(I6+5,0))) -> 8 | L6: =MAX(1,MIN(10,ROUNDUP(5-J6,0))) -> 1 | M6: =MIN(E6,F6) -> 1 | N6: concept+lexicon | O6: 0.56 | P6: 0 | Q6: desire, want | R6: self
